<?xml version="1.0" ?>
<!-- =================================================================================== -->
<!-- |    This document was autogenerated by xacro from khr3_001b.xacro                | -->
<!-- |    EDITING THIS FILE BY HAND IS NOT RECOMMENDED                                 | -->
<!-- =================================================================================== -->
<robot name="khr3_001">
  <material name="silver">
    <color rgba="0.700 0.700 0.700 1.000"/>
  </material>
  <material name="white">
    <color rgba="1.0 1.0 1.0 1.0"/>
  </material>
  <material name="black">
    <color rgba="0.0 0.0 0.0 1.0"/>
  </material>
  <transmission name="c_chest_yaw_tran" type="SimpleTransmission">
    <type>transmission_interface/SimpleTransmission</type>
    <joint name="c_chest_yaw">
      <hardwareInterface>hardware_interface/PositionJointInterface</hardwareInterface>
    </joint>
    <actuator name="c_chest_yaw_actr">
      <hardwareInterface>hardware_interface/PositionJointInterface</hardwareInterface>
      <mechanicalReduction>1</mechanicalReduction>
    </actuator>
  </transmission>
  <transmission name="c_head_yaw_tran" type="SimpleTransmission">
    <type>transmission_interface/SimpleTransmission</type>
    <joint name="c_head_yaw">
      <hardwareInterface>hardware_interface/PositionJointInterface</hardwareInterface>
    </joint>
    <actuator name="c_head_yaw_actr">
      <hardwareInterface>hardware_interface/PositionJointInterface</hardwareInterface>
      <mechanicalReduction>1</mechanicalReduction>
    </actuator>
  </transmission>
  <transmission name="l_shoulder_pitch_tran" type="SimpleTransmission">
    <type>transmission_interface/SimpleTransmission</type>
    <joint name="l_shoulder_pitch">
      <hardwareInterface>hardware_interface/PositionJointInterface</hardwareInterface>
    </joint>
    <actuator name="l_shoulder_pitch_actr">
      <hardwareInterface>hardware_interface/PositionJointInterface</hardwareInterface>
      <mechanicalReduction>1</mechanicalReduction>
    </actuator>
  </transmission>
  <transmission name="l_shoulder_roll_tran" type="SimpleTransmission">
    <type>transmission_interface/SimpleTransmission</type>
    <joint name="l_shoulder_roll">
      <hardwareInterface>hardware_interface/PositionJointInterface</hardwareInterface>
    </joint>
    <actuator name="l_shoulder_roll_actr">
      <hardwareInterface>hardware_interface/PositionJointInterface</hardwareInterface>
      <mechanicalReduction>1</mechanicalReduction>
    </actuator>
  </transmission>
  <transmission name="l_elbow_yaw_tran" type="SimpleTransmission">
    <type>transmission_interface/SimpleTransmission</type>
    <joint name="l_elbow_yaw">
      <hardwareInterface>hardware_interface/PositionJointInterface</hardwareInterface>
    </joint>
    <actuator name="l_elbow_yaw_actr">
      <hardwareInterface>hardware_interface/PositionJointInterface</hardwareInterface>
      <mechanicalReduction>1</mechanicalReduction>
    </actuator>
  </transmission>
  <transmission name="l_elbow_pitch_tran" type="SimpleTransmission">
    <type>transmission_interface/SimpleTransmission</type>
    <joint name="l_elbow_pitch">
      <hardwareInterface>hardware_interface/PositionJointInterface</hardwareInterface>
    </joint>
    <actuator name="l_elbow_pitch_actr">
      <hardwareInterface>hardware_interface/PositionJointInterface</hardwareInterface>
      <mechanicalReduction>1</mechanicalReduction>
    </actuator>
  </transmission>
  <transmission name="r_shoulder_pitch_tran" type="SimpleTransmission">
    <type>transmission_interface/SimpleTransmission</type>
    <joint name="r_shoulder_pitch">
      <hardwareInterface>hardware_interface/PositionJointInterface</hardwareInterface>
    </joint>
    <actuator name="r_shoulder_pitch_actr">
      <hardwareInterface>hardware_interface/PositionJointInterface</hardwareInterface>
      <mechanicalReduction>1</mechanicalReduction>
    </actuator>
  </transmission>
  <transmission name="r_shoulder_roll_tran" type="SimpleTransmission">
    <type>transmission_interface/SimpleTransmission</type>
    <joint name="r_shoulder_roll">
      <hardwareInterface>hardware_interface/PositionJointInterface</hardwareInterface>
    </joint>
    <actuator name="r_shoulder_roll_actr">
      <hardwareInterface>hardware_interface/PositionJointInterface</hardwareInterface>
      <mechanicalReduction>1</mechanicalReduction>
    </actuator>
  </transmission>
  <transmission name="r_elbow_yaw_tran" type="SimpleTransmission">
    <type>transmission_interface/SimpleTransmission</type>
    <joint name="r_elbow_yaw">
      <hardwareInterface>hardware_interface/PositionJointInterface</hardwareInterface>
    </joint>
    <actuator name="r_elbow_yaw_actr">
      <hardwareInterface>hardware_interface/PositionJointInterface</hardwareInterface>
      <mechanicalReduction>1</mechanicalReduction>
    </actuator>
  </transmission>
  <transmission name="r_elbow_pitch_tran" type="SimpleTransmission">
    <type>transmission_interface/SimpleTransmission</type>
    <joint name="r_elbow_pitch">
      <hardwareInterface>hardware_interface/PositionJointInterface</hardwareInterface>
    </joint>
    <actuator name="r_elbow_pitch_actr">
      <hardwareInterface>hardware_interface/PositionJointInterface</hardwareInterface>
      <mechanicalReduction>1</mechanicalReduction>
    </actuator>
  </transmission>
  <transmission name="l_hipjoint_yaw_tran" type="SimpleTransmission">
    <type>transmission_interface/SimpleTransmission</type>
    <joint name="l_hipjoint_yaw">
      <hardwareInterface>hardware_interface/PositionJointInterface</hardwareInterface>
    </joint>
    <actuator name="l_hipjoint_yaw_actr">
      <hardwareInterface>hardware_interface/PositionJointInterface</hardwareInterface>
      <mechanicalReduction>1</mechanicalReduction>
    </actuator>
  </transmission>
  <transmission name="l_hipjoint_roll_tran" type="SimpleTransmission">
    <type>transmission_interface/SimpleTransmission</type>
    <joint name="l_hipjoint_roll">
      <hardwareInterface>hardware_interface/PositionJointInterface</hardwareInterface>
    </joint>
    <actuator name="l_hipjoint_roll_actr">
      <hardwareInterface>hardware_interface/PositionJointInterface</hardwareInterface>
      <mechanicalReduction>1</mechanicalReduction>
    </actuator>
  </transmission>
  <transmission name="l_hipjoint_pitch_tran" type="SimpleTransmission">
    <type>transmission_interface/SimpleTransmission</type>
    <joint name="l_hipjoint_pitch">
      <hardwareInterface>hardware_interface/PositionJointInterface</hardwareInterface>
    </joint>
    <actuator name="l_hipjoint_pitch_actr">
      <hardwareInterface>hardware_interface/PositionJointInterface</hardwareInterface>
      <mechanicalReduction>1</mechanicalReduction>
    </actuator>
  </transmission>
  <transmission name="l_knee_pitch_tran" type="SimpleTransmission">
    <type>transmission_interface/SimpleTransmission</type>
    <joint name="l_knee_pitch">
      <hardwareInterface>hardware_interface/PositionJointInterface</hardwareInterface>
    </joint>
    <actuator name="l_knee_pitch_actr">
      <hardwareInterface>hardware_interface/PositionJointInterface</hardwareInterface>
      <mechanicalReduction>1</mechanicalReduction>
    </actuator>
  </transmission>
  <transmission name="l_ankle_pitch_tran" type="SimpleTransmission">
    <type>transmission_interface/SimpleTransmission</type>
    <joint name="l_ankle_pitch">
      <hardwareInterface>hardware_interface/PositionJointInterface</hardwareInterface>
    </joint>
    <actuator name="l_ankle_pitch_actr">
      <hardwareInterface>hardware_interface/PositionJointInterface</hardwareInterface>
      <mechanicalReduction>1</mechanicalReduction>
    </actuator>
  </transmission>
  <transmission name="l_ankle_roll_tran" type="SimpleTransmission">
    <type>transmission_interface/SimpleTransmission</type>
    <joint name="l_ankle_roll">
      <hardwareInterface>hardware_interface/PositionJointInterface</hardwareInterface>
    </joint>
    <actuator name="l_ankle_roll_actr">
      <hardwareInterface>hardware_interface/PositionJointInterface</hardwareInterface>
      <mechanicalReduction>1</mechanicalReduction>
    </actuator>
  </transmission>
  <transmission name="r_hipjoint_yaw_tran" type="SimpleTransmission">
    <type>transmission_interface/SimpleTransmission</type>
    <joint name="r_hipjoint_yaw">
      <hardwareInterface>hardware_interface/PositionJointInterface</hardwareInterface>
    </joint>
    <actuator name="r_hipjoint_yaw_actr">
      <hardwareInterface>hardware_interface/PositionJointInterface</hardwareInterface>
      <mechanicalReduction>1</mechanicalReduction>
    </actuator>
  </transmission>
  <transmission name="r_hipjoint_roll_tran" type="SimpleTransmission">
    <type>transmission_interface/SimpleTransmission</type>
    <joint name="r_hipjoint_roll">
      <hardwareInterface>hardware_interface/PositionJointInterface</hardwareInterface>
    </joint>
    <actuator name="r_hipjoint_roll_actr">
      <hardwareInterface>hardware_interface/PositionJointInterface</hardwareInterface>
      <mechanicalReduction>1</mechanicalReduction>
    </actuator>
  </transmission>
  <transmission name="r_hipjoint_pitch_tran" type="SimpleTransmission">
    <type>transmission_interface/SimpleTransmission</type>
    <joint name="r_hipjoint_pitch">
      <hardwareInterface>hardware_interface/PositionJointInterface</hardwareInterface>
    </joint>
    <actuator name="r_hipjoint_pitch_actr">
      <hardwareInterface>hardware_interface/PositionJointInterface</hardwareInterface>
      <mechanicalReduction>1</mechanicalReduction>
    </actuator>
  </transmission>
  <transmission name="r_knee_pitch_tran" type="SimpleTransmission">
    <type>transmission_interface/SimpleTransmission</type>
    <joint name="r_knee_pitch">
      <hardwareInterface>hardware_interface/PositionJointInterface</hardwareInterface>
    </joint>
    <actuator name="r_knee_pitch_actr">
      <hardwareInterface>hardware_interface/PositionJointInterface</hardwareInterface>
      <mechanicalReduction>1</mechanicalReduction>
    </actuator>
  </transmission>
  <transmission name="r_ankle_pitch_tran" type="SimpleTransmission">
    <type>transmission_interface/SimpleTransmission</type>
    <joint name="r_ankle_pitch">
      <hardwareInterface>hardware_interface/PositionJointInterface</hardwareInterface>
    </joint>
    <actuator name="r_ankle_pitch_actr">
      <hardwareInterface>hardware_interface/PositionJointInterface</hardwareInterface>
      <mechanicalReduction>1</mechanicalReduction>
    </actuator>
  </transmission>
  <transmission name="r_ankle_roll_tran" type="SimpleTransmission">
    <type>transmission_interface/SimpleTransmission</type>
    <joint name="r_ankle_roll">
      <hardwareInterface>hardware_interface/PositionJointInterface</hardwareInterface>
    </joint>
    <actuator name="r_ankle_roll_actr">
      <hardwareInterface>hardware_interface/PositionJointInterface</hardwareInterface>
      <mechanicalReduction>1</mechanicalReduction>
    </actuator>
  </transmission>
  <!-- <gazebo>
  <plugin name="control" filename="libgazebo_ros_control.so"/>
</gazebo> -->
  <gazebo>
    <!-- Do I have to write it down? -->
    <plugin filename="libgazebo_ros_control.so" name="gazebo_ros_control">
      <robotNamespace>/khr3_001</robotNamespace>
      <robotSimType>gazebo_ros_control/DefaultRobotHWSim</robotSimType>
    </plugin>
  </gazebo>
  <gazebo reference="base_link">
    <material>Gazebo/Silver</material>
    <mu1>0.2</mu1>
    <mu2>0.2</mu2>
    <selfCollide>true</selfCollide>
    <gravity>true</gravity>
  </gazebo>
  <gazebo reference="c_chest_c">
    <material>Gazebo/Silver</material>
    <mu1>0.2</mu1>
    <mu2>0.2</mu2>
    <selfCollide>true</selfCollide>
  </gazebo>
  <gazebo reference="c_chest_b">
    <material>Gazebo/Silver</material>
    <mu1>0.2</mu1>
    <mu2>0.2</mu2>
    <selfCollide>true</selfCollide>
  </gazebo>
  <gazebo reference="c_chest_a">
    <material>Gazebo/Silver</material>
    <mu1>0.2</mu1>
    <mu2>0.2</mu2>
    <selfCollide>true</selfCollide>
  </gazebo>
  <gazebo reference="c_head_a">
    <material>Gazebo/Silver</material>
    <mu1>0.2</mu1>
    <mu2>0.2</mu2>
    <selfCollide>true</selfCollide>
  </gazebo>
  <gazebo reference="l_shoulder">
    <material>Gazebo/Silver</material>
    <mu1>0.2</mu1>
    <mu2>0.2</mu2>
    <selfCollide>true</selfCollide>
  </gazebo>
  <gazebo reference="l_upperarm">
    <material>Gazebo/Silver</material>
    <mu1>0.2</mu1>
    <mu2>0.2</mu2>
    <selfCollide>true</selfCollide>
  </gazebo>
  <gazebo reference="l_elbow">
    <material>Gazebo/Silver</material>
    <mu1>0.2</mu1>
    <mu2>0.2</mu2>
    <selfCollide>true</selfCollide>
  </gazebo>
  <gazebo reference="l_lowerarm">
    <material>Gazebo/Silver</material>
    <mu1>0.2</mu1>
    <mu2>0.2</mu2>
    <selfCollide>true</selfCollide>
  </gazebo>
  <gazebo reference="r_shoulder">
    <material>Gazebo/Silver</material>
    <mu1>0.2</mu1>
    <mu2>0.2</mu2>
    <selfCollide>true</selfCollide>
  </gazebo>
  <gazebo reference="r_upperarm">
    <material>Gazebo/Silver</material>
    <mu1>0.2</mu1>
    <mu2>0.2</mu2>
    <selfCollide>true</selfCollide>
  </gazebo>
  <gazebo reference="r_elbow">
    <material>Gazebo/Silver</material>
    <mu1>0.2</mu1>
    <mu2>0.2</mu2>
    <selfCollide>true</selfCollide>
  </gazebo>
  <gazebo reference="r_lowerarm">
    <material>Gazebo/Silver</material>
    <mu1>0.2</mu1>
    <mu2>0.2</mu2>
    <selfCollide>true</selfCollide>
  </gazebo>
  <gazebo reference="l_hipjointupper">
    <material>Gazebo/Silver</material>
    <mu1>0.2</mu1>
    <mu2>0.2</mu2>
    <selfCollide>true</selfCollide>
  </gazebo>
  <gazebo reference="l_hipjointlower">
    <material>Gazebo/Silver</material>
    <mu1>0.2</mu1>
    <mu2>0.2</mu2>
    <selfCollide>true</selfCollide>
  </gazebo>
  <gazebo reference="l_upperleg">
    <material>Gazebo/Silver</material>
    <mu1>0.2</mu1>
    <mu2>0.2</mu2>
    <selfCollide>true</selfCollide>
  </gazebo>
  <gazebo reference="l_lowerleg">
    <material>Gazebo/Silver</material>
    <mu1>0.2</mu1>
    <mu2>0.2</mu2>
    <selfCollide>true</selfCollide>
  </gazebo>
  <gazebo reference="l_ankle">
    <material>Gazebo/Silver</material>
    <mu1>0.2</mu1>
    <mu2>0.2</mu2>
    <selfCollide>true</selfCollide>
  </gazebo>
  <gazebo reference="l_foot">
    <material>Gazebo/Silver</material>
    <mu1>1</mu1>
    <mu2>1</mu2>
    <selfCollide>true</selfCollide>
  </gazebo>
  <gazebo reference="r_hipjointupper">
    <material>Gazebo/Silver</material>
    <mu1>0.2</mu1>
    <mu2>0.2</mu2>
    <selfCollide>true</selfCollide>
  </gazebo>
  <gazebo reference="r_hipjointlower">
    <material>Gazebo/Silver</material>
    <mu1>0.2</mu1>
    <mu2>0.2</mu2>
    <selfCollide>true</selfCollide>
  </gazebo>
  <gazebo reference="r_upperleg">
    <material>Gazebo/Silver</material>
    <mu1>0.2</mu1>
    <mu2>0.2</mu2>
    <selfCollide>true</selfCollide>
  </gazebo>
  <gazebo reference="r_lowerleg">
    <material>Gazebo/Silver</material>
    <mu1>0.2</mu1>
    <mu2>0.2</mu2>
    <selfCollide>true</selfCollide>
  </gazebo>
  <gazebo reference="r_ankle">
    <material>Gazebo/Silver</material>
    <mu1>0.2</mu1>
    <mu2>0.2</mu2>
    <selfCollide>true</selfCollide>
  </gazebo>
  <gazebo reference="r_foot">
    <material>Gazebo/Silver</material>
    <mu1>1</mu1>
    <mu2>1</mu2>
    <selfCollide>true</selfCollide>
  </gazebo>
  <!-- Description of robot -->
  <link name="base_footprint">
  </link>
  <link name="base_link">
    <inertial>
      <origin rpy="0 0 0" xyz="-0.0004860989233068058 0.009532810756286874 0.01338898"/>
      <mass value="0.26484"/>
      <inertia ixx="6.3e-05" ixy="0.0" ixz="-0.0" iyy="3.6e-05" iyz="-0.0" izz="6.8e-05"/>
    </inertial>
    <visual>
      <origin rpy="0 0 0" xyz="0 0 0"/>
      <geometry>
        <mesh filename="package://khr3_fixed/meshes/base_link.stl" scale="0.001 0.001 0.001"/>
      </geometry>
      <material name="black"/>
    </visual>
    <collision>
      <origin rpy="0 0 0" xyz="0 0 0"/>
      <geometry>
        <mesh filename="package://khr3_fixed/meshes/base_link.stl" scale="0.001 0.001 0.001"/>
      </geometry>
    </collision>
  </link>
  <link name="c_chest_c">
    <inertial>
      <origin rpy="0 0 0" xyz="-9.07564737343998e-05 -4.299695898109246e-08 0.04371354326547944"/>
      <mass value="0.18589"/>
      <inertia ixx="0.000158" ixy="0.0" ixz="0.0" iyy="6.6e-05" iyz="-0.0" izz="0.000176"/>
    </inertial>
    <visual>
      <origin rpy="0 0 0" xyz="0 0 0"/>
      <geometry>
        <mesh filename="package://khr3_fixed/meshes/c_chest_c.stl" scale="0.001 0.001 0.001"/>
      </geometry>
      <material name="silver"/>
    </visual>
    <collision>
      <origin rpy="0 0 0" xyz="0 0 0"/>
      <geometry>
        <mesh filename="package://khr3_fixed/meshes/c_chest_c.stl" scale="0.001 0.001 0.001"/>
      </geometry>
    </collision>
  </link>
  <link name="c_chest_b">
    <inertial>
      <origin rpy="0 0 0" xyz="-0.027362562372520854 2.840518613928325e-06 0.004477857770456339"/>
      <mass value="0.08659748664099903"/>
      <inertia ixx="0.000118" ixy="0.0" ixz="0.0" iyy="5.2e-05" iyz="0.0" izz="9.8e-05"/>
    </inertial>
    <visual>
      <origin rpy="0 0 0" xyz="0 0 0"/>
      <geometry>
        <mesh filename="package://khr3_fixed/meshes/c_chest_b.stl" scale="0.001 0.001 0.001"/>
      </geometry>
      <material name="black"/>
    </visual>
    <collision>
      <origin rpy="0 0 0" xyz="0 0 0"/>
      <geometry>
        <mesh filename="package://khr3_fixed/meshes/c_chest_b.stl" scale="0.001 0.001 0.001"/>
      </geometry>
    </collision>
  </link>
  <link name="c_chest_a">
    <inertial>
      <origin rpy="0 0 0" xyz="0.004546800382866728 -4.1161282904669805e-08 -0.0024788373011201403"/>
      <mass value="0.033763915303500654"/>
      <inertia ixx="3.4e-05" ixy="-0.0" ixz="-3e-06" iyy="1.9e-05" iyz="0.0" izz="3.6e-05"/>
    </inertial>
    <visual>
      <origin rpy="0 0 0" xyz="0 0 0"/>
      <geometry>
        <mesh filename="package://khr3_fixed/meshes/c_chest_a.stl" scale="0.001 0.001 0.001"/>
      </geometry>
      <material name="silver"/>
    </visual>
    <collision>
      <origin rpy="0 0 0" xyz="0 0 0"/>
      <geometry>
        <mesh filename="package://khr3_fixed/meshes/c_chest_a.stl" scale="0.001 0.001 0.001"/>
      </geometry>
    </collision>
  </link>
  <link name="c_head_a">
    <inertial>
      <origin rpy="0 0 0" xyz="0.003079433021973575 -4.3073247395913894e-08 0.022888877386975093"/>
      <mass value="0.012778861662402228"/>
      <inertia ixx="2e-06" ixy="-0.0" ixz="-0.0" iyy="4e-06" iyz="0.0" izz="3e-06"/>
    </inertial>
    <visual>
      <origin rpy="0 0 0" xyz="0 0 0"/>
      <geometry>
        <mesh filename="package://khr3_fixed/meshes/c_head_a.stl" scale="0.001 0.001 0.001"/>
      </geometry>
      <material name="silver"/>
    </visual>
    <collision>
      <origin rpy="0 0 0" xyz="0 0 0"/>
      <geometry>
        <mesh filename="package://khr3_fixed/meshes/c_head_a.stl" scale="0.001 0.001 0.001"/>
      </geometry>
    </collision>
  </link>
  <link name="l_shoulder">
    <inertial>
      <origin rpy="0 0 0" xyz="0.00016940373751364937 0.008747288709026461 3.2529534621517087e-14"/>
      <mass value="0.012120367829212707"/>
      <inertia ixx="1e-06" ixy="-0.0" ixz="0.0" iyy="4e-06" iyz="0.0" izz="4e-06"/>
    </inertial>
    <visual>
      <origin rpy="0 0 0" xyz="0 0 0"/>
      <geometry>
        <mesh filename="package://khr3_fixed/meshes/l_shoulder_v5.stl" scale="0.001 0.001 0.001"/>
      </geometry>
      <material name="black"/>
    </visual>
    <collision>
      <origin rpy="0 0 0" xyz="0 0 0"/>
      <geometry>
        <mesh filename="package://khr3_fixed/meshes/l_shoulder_v5.stl" scale="0.001 0.001 0.001"/>
      </geometry>
    </collision>
  </link>
  <link name="l_upperarm">
    <inertial>
      <origin rpy="0 0 0" xyz="-0.02256531849252991 -4.2996961130414846e-08 -0.03564584515249991"/>
      <mass value="0.09077338253436838"/>
      <inertia ixx="5.4e-05" ixy="0.0" ixz="-1e-05" iyy="6.4e-05" iyz="0.0" izz="1.8e-05"/>
    </inertial>
    <visual>
      <origin rpy="0 0 0" xyz="0 0 0"/>
      <geometry>
        <mesh filename="package://khr3_fixed/meshes/l_upperarm_v4.stl" scale="0.001 0.001 0.001"/>
      </geometry>
      <material name="silver"/>
    </visual>
    <collision>
      <origin rpy="0 0 0" xyz="0 0 0"/>
      <geometry>
        <mesh filename="package://khr3_fixed/meshes/l_upperarm_v4.stl" scale="0.001 0.001 0.001"/>
      </geometry>
    </collision>
  </link>
  <link name="l_elbow">
    <inertial>
      <origin rpy="0 0 0" xyz="5.745484729775818e-05 -4.299695875731313e-08 -0.012574921301198305"/>
      <mass value="0.044771268874731644"/>
      <inertia ixx="6e-06" ixy="0.0" ixz="0.0" iyy="8e-06" iyz="-0.0" izz="1e-05"/>
    </inertial>
    <visual>
      <origin rpy="0 0 0" xyz="0 0 0"/>
      <geometry>
        <mesh filename="package://khr3_fixed/meshes/l_elbow_v4.stl" scale="0.001 0.001 0.001"/>
      </geometry>
      <material name="black"/>
    </visual>
    <collision>
      <origin rpy="0 0 0" xyz="0 0 0"/>
      <geometry>
        <mesh filename="package://khr3_fixed/meshes/l_elbow_v4.stl" scale="0.001 0.001 0.001"/>
      </geometry>
    </collision>
  </link>
  <link name="l_lowerarm">
    <inertial>
      <origin rpy="0 0 0" xyz="0.00017641899363149416 -0.0156924274010031 -0.04569649848488025"/>
      <mass value="0.02983803452815617"/>
      <inertia ixx="1.8e-05" ixy="0.0" ixz="0.0" iyy="1.6e-05" iyz="-0.0" izz="4e-06"/>
    </inertial>
    <visual>
      <origin rpy="0 0 0" xyz="0 0 0"/>
      <geometry>
        <mesh filename="package://khr3_fixed/meshes/l_lowerarm_v7.stl" scale="0.001 0.001 0.001"/>
      </geometry>
      <material name="silver"/>
    </visual>
    <collision>
      <origin rpy="0 0 0" xyz="0 0 0"/>
      <geometry>
        <mesh filename="package://khr3_fixed/meshes/l_lowerarm_v7.stl" scale="0.001 0.001 0.001"/>
      </geometry>
    </collision>
  </link>
  <link name="r_shoulder">
    <inertial>
      <origin rpy="0 0 0" xyz="0.00016940373733528857 -0.008747374702943796 5.306866057708248e-14"/>
      <mass value="0.01212036782921271"/>
      <inertia ixx="1e-06" ixy="0.0" ixz="-0.0" iyy="4e-06" iyz="0.0" izz="4e-06"/>
    </inertial>
    <visual>
      <origin rpy="0 0 0" xyz="0 0 0"/>
      <geometry>
        <mesh filename="package://khr3_fixed/meshes/r_shoulder_v4.stl" scale="0.001 0.001 0.001"/>
      </geometry>
      <material name="black"/>
    </visual>
    <collision>
      <origin rpy="0 0 0" xyz="0 0 0"/>
      <geometry>
        <mesh filename="package://khr3_fixed/meshes/r_shoulder_v4.stl" scale="0.001 0.001 0.001"/>
      </geometry>
    </collision>
  </link>
  <link name="r_upperarm">
    <inertial>
      <origin rpy="0 0 0" xyz="-0.022565318492529688 -4.2996961074903695e-08 -0.03564584515249991"/>
      <mass value="0.09077338253436838"/>
      <inertia ixx="5.4e-05" ixy="0.0" ixz="-1e-05" iyy="6.4e-05" iyz="0.0" izz="1.8e-05"/>
    </inertial>
    <visual>
      <origin rpy="0 0 0" xyz="0 0 0"/>
      <geometry>
        <mesh filename="package://khr3_fixed/meshes/r_upperarm_v3.stl" scale="0.001 0.001 0.001"/>
      </geometry>
      <material name="silver"/>
    </visual>
    <collision>
      <origin rpy="0 0 0" xyz="0 0 0"/>
      <geometry>
        <mesh filename="package://khr3_fixed/meshes/r_upperarm_v3.stl" scale="0.001 0.001 0.001"/>
      </geometry>
    </collision>
  </link>
  <link name="r_elbow">
    <inertial>
      <origin rpy="0 0 0" xyz="5.7454847330103836e-05 -4.2996958674046404e-08 -0.012574921301198305"/>
      <mass value="0.044771268874731526"/>
      <inertia ixx="6e-06" ixy="0.0" ixz="0.0" iyy="8e-06" iyz="-0.0" izz="1e-05"/>
    </inertial>
    <visual>
      <origin rpy="0 0 0" xyz="0 0 0"/>
      <geometry>
        <mesh filename="package://khr3_fixed/meshes/r_elbow_v4.stl" scale="0.001 0.001 0.001"/>
      </geometry>
      <material name="black"/>
    </visual>
    <collision>
      <origin rpy="0 0 0" xyz="0 0 0"/>
      <geometry>
        <mesh filename="package://khr3_fixed/meshes/r_elbow_v4.stl" scale="0.001 0.001 0.001"/>
      </geometry>
    </collision>
  </link>
  <link name="r_lowerarm">
    <inertial>
      <origin rpy="0 0 0" xyz="0.00017641899364317232 0.01569234140705124 -0.04569649848495705"/>
      <mass value="0.029838034528201704"/>
      <inertia ixx="1.8e-05" ixy="-0.0" ixz="0.0" iyy="1.6e-05" iyz="0.0" izz="4e-06"/>
    </inertial>
    <visual>
      <origin rpy="0 0 0" xyz="0 0 0"/>
      <geometry>
        <mesh filename="package://khr3_fixed/meshes/r_lowerarm_v5.stl" scale="0.001 0.001 0.001"/>
      </geometry>
      <material name="silver"/>
    </visual>
    <collision>
      <origin rpy="0 0 0" xyz="0 0 0"/>
      <geometry>
        <mesh filename="package://khr3_fixed/meshes/r_lowerarm_v5.stl" scale="0.001 0.001 0.001"/>
      </geometry>
    </collision>
  </link>
  <link name="l_hipjointupper">
    <inertial>
      <origin rpy="0 0 0" xyz="3.293764515496962e-05 -0.0011113374509284651 -0.007400199793976242"/>
      <mass value="0.005702042499396512"/>
      <inertia ixx="1e-06" ixy="0.0" ixz="0.0" iyy="2e-06" iyz="-0.0" izz="2e-06"/>
    </inertial>
    <visual>
      <origin rpy="0 0 0" xyz="0 0 0"/>
      <geometry>
        <mesh filename="package://khr3_fixed/meshes/l_hipjointupper_v4.stl" scale="0.001 0.001 0.001"/>
      </geometry>
      <material name="silver"/>
    </visual>
    <collision>
      <origin rpy="0 0 0" xyz="0 0 0"/>
      <geometry>
        <mesh filename="package://khr3_fixed/meshes/l_hipjointupper_v4.stl" scale="0.001 0.001 0.001"/>
      </geometry>
    </collision>
  </link>
  <link name="l_hipjointlower">
    <inertial>
      <origin rpy="0 0 0" xyz="-0.016250242301438553 0.011463181378816707 -0.0066539419866288585"/>
      <mass value="0.06689532645492419"/>
      <inertia ixx="2e-05" ixy="0.0" ixz="-0.0" iyy="1.4e-05" iyz="0.0" izz="1.5e-05"/>
    </inertial>
    <visual>
      <origin rpy="0 0 0" xyz="0 0 0"/>
      <geometry>
        <mesh filename="package://khr3_fixed/meshes/l_hipjointlower_v4.stl" scale="0.001 0.001 0.001"/>
      </geometry>
      <material name="black"/>
    </visual>
    <collision>
      <origin rpy="0 0 0" xyz="0 0 0"/>
      <geometry>
        <mesh filename="package://khr3_fixed/meshes/l_hipjointlower_v4.stl" scale="0.001 0.001 0.001"/>
      </geometry>
    </collision>
  </link>
  <link name="l_upperleg">
    <inertial>
      <origin rpy="0 0 0" xyz="0.002589780466551929 -0.016500042996958703 -0.03375567398425394"/>
      <mass value="0.09097466003274825"/>
      <inertia ixx="5.9e-05" ixy="0.0" ixz="4e-06" iyy="5.6e-05" iyz="0.0" izz="1.3e-05"/>
    </inertial>
    <visual>
      <origin rpy="0 0 0" xyz="0 0 0"/>
      <geometry>
        <mesh filename="package://khr3_fixed/meshes/l_upperleg_v3.stl" scale="0.001 0.001 0.001"/>
      </geometry>
      <material name="silver"/>
    </visual>
    <collision>
      <origin rpy="0 0 0" xyz="0 0 0"/>
      <geometry>
        <mesh filename="package://khr3_fixed/meshes/l_upperleg_v3.stl" scale="0.001 0.001 0.001"/>
      </geometry>
    </collision>
  </link>
  <link name="l_lowerleg">
    <inertial>
      <origin rpy="0 0 0" xyz="0.0044805681524230055 -0.015970110512676966 -0.04182100713444817"/>
      <mass value="0.06094435150357522"/>
      <inertia ixx="2.9e-05" ixy="0.0" ixz="-5e-06" iyy="2.6e-05" iyz="-0.0" izz="1.1e-05"/>
    </inertial>
    <visual>
      <origin rpy="0 0 0" xyz="0 0 0"/>
      <geometry>
        <mesh filename="package://khr3_fixed/meshes/l_lowerleg_v5.stl" scale="0.001 0.001 0.001"/>
      </geometry>
      <material name="black"/>
    </visual>
    <collision>
      <origin rpy="0 0 0" xyz="0 0 0"/>
      <geometry>
        <mesh filename="package://khr3_fixed/meshes/l_lowerleg_v5.stl" scale="0.001 0.001 0.001"/>
      </geometry>
    </collision>
  </link>
  <link name="l_ankle">
    <inertial>
      <origin rpy="0 0 0" xyz="0.0001886240331466279 -0.01666391069306302 -0.03292964719213733"/>
      <mass value="0.06757551562559608"/>
      <inertia ixx="2e-05" ixy="0.0" ixz="0.0" iyy="1.4e-05" iyz="-0.0" izz="1.6e-05"/>
    </inertial>
    <visual>
      <origin rpy="0 0 0" xyz="0 0 0"/>
      <geometry>
        <mesh filename="package://khr3_fixed/meshes/l_ankle_v5.stl" scale="0.001 0.001 0.001"/>
      </geometry>
      <material name="silver"/>
    </visual>
    <collision>
      <origin rpy="0 0 0" xyz="0 0 0"/>
      <geometry>
        <mesh filename="package://khr3_fixed/meshes/l_ankle_v5.stl" scale="0.001 0.001 0.001"/>
      </geometry>
    </collision>
  </link>
  <link name="l_foot">
    <inertial>
      <origin rpy="0 0 0" xyz="-0.020700151207673705 0.023895172544662873 -0.021244534057561063"/>
      <mass value="0.03847104970565043"/>
      <inertia ixx="2.3e-05" ixy="-0.0" ixz="0.0" iyy="4.8e-05" iyz="0.0" izz="6.9e-05"/>
    </inertial>
    <visual>
      <origin rpy="0 0 0" xyz="0 0 0"/>
      <geometry>
        <mesh filename="package://khr3_fixed/meshes/l_foot_v3.stl" scale="0.001 0.001 0.001"/>
      </geometry>
      <material name="black"/>
    </visual>
    <collision>
      <origin rpy="0 0 0" xyz="0 0 0"/>
      <geometry>
        <mesh filename="package://khr3_fixed/meshes/l_foot_v3.stl" scale="0.001 0.001 0.001"/>
      </geometry>
    </collision>
  </link>
  <link name="r_hipjointupper">
    <inertial>
      <origin rpy="0 0 0" xyz="3.2937645155054623e-05 0.0011112514569246185 -0.007400199793976325"/>
      <mass value="0.005702042499396526"/>
      <inertia ixx="1e-06" ixy="-0.0" ixz="0.0" iyy="2e-06" iyz="0.0" izz="2e-06"/>
    </inertial>
    <visual>
      <origin rpy="0 0 0" xyz="0 0 0"/>
      <geometry>
        <mesh filename="package://khr3_fixed/meshes/r_hipjointupper_v4.stl" scale="0.001 0.001 0.001"/>
      </geometry>
      <material name="silver"/>
    </visual>
    <collision>
      <origin rpy="0 0 0" xyz="0 0 0"/>
      <geometry>
        <mesh filename="package://khr3_fixed/meshes/r_hipjointupper_v4.stl" scale="0.001 0.001 0.001"/>
      </geometry>
    </collision>
  </link>
  <link name="r_hipjointlower">
    <inertial>
      <origin rpy="0 0 0" xyz="-0.016250242301436166 -0.011463267372574608 -0.006653941986625556"/>
      <mass value="0.0668953264549242"/>
      <inertia ixx="2e-05" ixy="0.0" ixz="0.0" iyy="1.4e-05" iyz="-0.0" izz="1.5e-05"/>
    </inertial>
    <visual>
      <origin rpy="0 0 0" xyz="0 0 0"/>
      <geometry>
        <mesh filename="package://khr3_fixed/meshes/r_hipjointlower_v4.stl" scale="0.001 0.001 0.001"/>
      </geometry>
      <material name="black"/>
    </visual>
    <collision>
      <origin rpy="0 0 0" xyz="0 0 0"/>
      <geometry>
        <mesh filename="package://khr3_fixed/meshes/r_hipjointlower_v4.stl" scale="0.001 0.001 0.001"/>
      </geometry>
    </collision>
  </link>
  <link name="r_upperleg">
    <inertial>
      <origin rpy="0 0 0" xyz="0.0025897804665520278 0.016499957003041386 -0.03375567398425397"/>
      <mass value="0.09097466003274823"/>
      <inertia ixx="5.9e-05" ixy="-0.0" ixz="4e-06" iyy="5.6e-05" iyz="0.0" izz="1.3e-05"/>
    </inertial>
    <visual>
      <origin rpy="0 0 0" xyz="0 0 0"/>
      <geometry>
        <mesh filename="package://khr3_fixed/meshes/r_upperleg_v3.stl" scale="0.001 0.001 0.001"/>
      </geometry>
      <material name="silver"/>
    </visual>
    <collision>
      <origin rpy="0 0 0" xyz="0 0 0"/>
      <geometry>
        <mesh filename="package://khr3_fixed/meshes/r_upperleg_v3.stl" scale="0.001 0.001 0.001"/>
      </geometry>
    </collision>
  </link>
  <link name="r_lowerleg">
    <inertial>
      <origin rpy="0 0 0" xyz="0.004480568152423165 0.01597002451875967 -0.04182100713444818"/>
      <mass value="0.06094435150357523"/>
      <inertia ixx="2.9e-05" ixy="-0.0" ixz="-5e-06" iyy="2.6e-05" iyz="0.0" izz="1.1e-05"/>
    </inertial>
    <visual>
      <origin rpy="0 0 0" xyz="0 0 0"/>
      <geometry>
        <mesh filename="package://khr3_fixed/meshes/r_lowerleg_v5.stl" scale="0.001 0.001 0.001"/>
      </geometry>
      <material name="black"/>
    </visual>
    <collision>
      <origin rpy="0 0 0" xyz="0 0 0"/>
      <geometry>
        <mesh filename="package://khr3_fixed/meshes/r_lowerleg_v5.stl" scale="0.001 0.001 0.001"/>
      </geometry>
    </collision>
  </link>
  <link name="r_ankle">
    <inertial>
      <origin rpy="0 0 0" xyz="0.00018862403314765484 0.01666382469921859 -0.03292964719213813"/>
      <mass value="0.06757551562559609"/>
      <inertia ixx="2e-05" ixy="-0.0" ixz="0.0" iyy="1.4e-05" iyz="0.0" izz="1.6e-05"/>
    </inertial>
    <visual>
      <origin rpy="0 0 0" xyz="0 0 0"/>
      <geometry>
        <mesh filename="package://khr3_fixed/meshes/r_ankle_v5.stl" scale="0.001 0.001 0.001"/>
      </geometry>
      <material name="silver"/>
    </visual>
    <collision>
      <origin rpy="0 0 0" xyz="0 0 0"/>
      <geometry>
        <mesh filename="package://khr3_fixed/meshes/r_ankle_v5.stl" scale="0.001 0.001 0.001"/>
      </geometry>
    </collision>
  </link>
  <link name="r_foot">
    <inertial>
      <origin rpy="0 0 0" xyz="-0.020700151207566492 -0.023895258538579878 -0.02124453405755709"/>
      <mass value="0.03847104970565037"/>
      <inertia ixx="2.3e-05" ixy="-0.0" ixz="-0.0" iyy="4.8e-05" iyz="-0.0" izz="6.9e-05"/>
    </inertial>
    <visual>
      <origin rpy="0 0 0" xyz="0 0 0"/>
      <geometry>
        <mesh filename="package://khr3_fixed/meshes/r_foot_v3.stl" scale="0.001 0.001 0.001"/>
      </geometry>
      <material name="black"/>
    </visual>
    <collision>
      <origin rpy="0 0 0" xyz="0 0 0"/>
      <geometry>
        <mesh filename="package://khr3_fixed/meshes/r_foot_v3.stl" scale="0.001 0.001 0.001"/>
      </geometry>
    </collision>
  </link>
  <!-- continuous <-> revolute -->
  <joint name="floating_joint" type="fixed">
    <parent link="base_footprint"/>
    <child link="base_link"/>
    <origin rpy="0 0 0" xyz="0 0 0.257663"/>
  </joint>
  <joint name="c_chest_yaw" type="revolute">
    <origin rpy="0 0 0" xyz="0 0 0.039"/>
    <parent link="base_link"/>
    <child link="c_chest_c"/>
    <axis xyz="0.0 -0.0 1.0"/>
    <limit effort="1.373" lower="-0.6981317008" upper="0.6981317008" velocity="10.0"/>
  </joint>
  <joint name="intrgration_01" type="fixed">
    <origin rpy="0 0 0" xyz="-0.026 0.0 0.03125"/>
    <parent link="c_chest_c"/>
    <child link="c_chest_b"/>
  </joint>
  <joint name="intrgration_02" type="fixed">
    <origin rpy="0 0 0" xyz="0.026 0.0 0.03125"/>
    <parent link="c_chest_c"/>
    <child link="c_chest_a"/>
  </joint>
  <joint name="l_shoulder_pitch" type="revolute">
    <origin rpy="0 0 0" xyz="0.0115 0.0489 0.04775"/>
    <parent link="c_chest_c"/>
    <child link="l_shoulder"/>
    <axis xyz="-0.0 1.0 0.0"/>
    <limit effort="1.373" lower="-2.268928028" upper="2.268928028" velocity="10.0"/>
  </joint>
  <joint name="l_shoulder_roll" type="revolute">
    <origin rpy="0 0 0" xyz="0.01575 0.025 0.0"/>
    <parent link="l_shoulder"/>
    <child link="l_upperarm"/>
    <axis xyz="1.0 -0.0 0.0"/>
    <limit effort="1.373" lower="-0.0872664626" upper="3.141592654" velocity="10.0"/>
  </joint>
  <joint name="l_elbow_yaw" type="revolute">
    <origin rpy="0 0 0" xyz="-0.016 0.0 -0.07175"/>
    <parent link="l_upperarm"/>
    <child link="l_elbow"/>
    <axis xyz="-0.0 -0.0 1.0"/>
    <limit effort="1.373" lower="-1.5707963267948966" upper="1.5707963267948966" velocity="10.0"/>
  </joint>
  <joint name="l_elbow_pitch" type="revolute">
    <origin rpy="0 0 0" xyz="0.0115 0.01625 -0.0145"/>
    <parent link="l_elbow"/>
    <child link="l_lowerarm"/>
    <axis xyz="-0.0 1.0 0.0"/>
    <limit effort="1.373" lower="-2.094395102" upper="0.5235987756" velocity="10.0"/>
  </joint>
  <joint name="l_hipjoint_yaw" type="revolute">
    <origin rpy="0 0 0" xyz="0 0.02170 0"/>
    <parent link="base_link"/>
    <child link="l_hipjointupper"/>
    <axis xyz="-0.0 0.0 -1.0"/>
    <limit effort="1.373" lower="-0.3490658504" upper="0.3490658504" velocity="10.0"/>
  </joint>
  <joint name="l_hipjoint_roll" type="revolute">
    <origin rpy="0 0 0" xyz="0.0167 -0.004 -0.02275"/>
    <parent link="l_hipjointupper"/>
    <child link="l_hipjointlower"/>
    <axis xyz="1.0 0.0 -0.0"/>
    <limit effort="1.373" lower="-0.3490658504" upper="0.436332313" velocity="10.0"/>
  </joint>
  <joint name="l_hipjoint_pitch" type="revolute">
    <origin rpy="0 0 0" xyz="-0.01625 0.0275 -0.0395"/>
    <parent link="l_hipjointlower"/>
    <child link="l_upperleg"/>
    <axis xyz="-0.0 1.0 0.0"/>
    <limit effort="1.373" lower="-1.919862177" upper="1.745329252" velocity="10.0"/>
  </joint>
  <joint name="l_knee_pitch" type="revolute">
    <origin rpy="0 0 0" xyz="0.0 0.0 -0.065"/>
    <parent link="l_upperleg"/>
    <child link="l_lowerleg"/>
    <axis xyz="-0.0 1.0 0.0"/>
    <limit effort="1.373" lower="0.0" upper="2.792526803" velocity="10.0"/>
  </joint>
  <joint name="l_ankle_pitch" type="revolute">
    <origin rpy="0 0 0" xyz="-0.003363 0.0005 -0.064913"/>
    <parent link="l_lowerleg"/>
    <child link="l_ankle"/>
    <axis xyz="0.0 1.0 0.0"/>
    <limit effort="1.373" lower="-1.5707963267948966" upper="1.745329252" velocity="10.0"/>
  </joint>
  <joint name="l_ankle_roll" type="revolute">
    <origin rpy="0 0 0" xyz="0.01975 -0.028 -0.0395"/>
    <parent link="l_ankle"/>
    <child link="l_foot"/>
    <axis xyz="1.0 -0.0 -0.0"/>
    <limit effort="1.373" lower="-0.5235987756" upper="0.3490658504" velocity="10.0"/>
  </joint>
  <joint name="c_head_yaw" type="revolute">
    <origin rpy="0 0 0" xyz="0.0115 0.0 0.0595"/>
    <parent link="c_chest_c"/>
    <child link="c_head_a"/>
    <axis xyz="0.0 -0.0 1.0"/>
    <limit effort="1.373" lower="-1.5707963267948966" upper="1.5707963267948966" velocity="10.0"/>
  </joint>
  <joint name="r_shoulder_pitch" type="revolute">
    <origin rpy="0 0 0" xyz="0.0115 -0.0489 0.04775"/>
    <parent link="c_chest_c"/>
    <child link="r_shoulder"/>
    <axis xyz="0.0 -1.0 -0.0"/>
    <limit effort="1.373" lower="-2.268928028" upper="2.268928028" velocity="10.0"/>
  </joint>
  <joint name="r_shoulder_roll" type="revolute">
    <origin rpy="0 0 0" xyz="0.01575 -0.025 0.0"/>
    <parent link="r_shoulder"/>
    <child link="r_upperarm"/>
    <axis xyz="1.0 0.0 0.0"/>
    <limit effort="1.373" lower="-3.141592654" upper="0.0872664626" velocity="10.0"/>
  </joint>
  <joint name="r_elbow_yaw" type="revolute">
    <origin rpy="0 0 0" xyz="-0.016 0.0 -0.07175"/>
    <parent link="r_upperarm"/>
    <child link="r_elbow"/>
    <axis xyz="-0.0 0.0 1.0"/>
    <limit effort="1.373" lower="-1.5707963267948966" upper="1.5707963267948966" velocity="10.0"/>
  </joint>
  <joint name="r_elbow_pitch" type="revolute">
    <origin rpy="0 0 0" xyz="0.0115 -0.01625 -0.0145"/>
    <parent link="r_elbow"/>
    <child link="r_lowerarm"/>
    <axis xyz="-0.0 1.0 -0.0"/>
    <limit effort="1.373" lower="-2.094395102" upper="0.5235987756" velocity="10.0"/>
  </joint>
  <joint name="r_hipjoint_yaw" type="revolute">
    <origin rpy="0 0 0" xyz="0 -0.02170 0"/>
    <parent link="base_link"/>
    <child link="r_hipjointupper"/>
    <axis xyz="-0.0 0.0 -1.0"/>
    <limit effort="1.373" lower="-0.3490658504" upper="0.3490658504" velocity="10.0"/>
  </joint>
  <joint name="r_hipjoint_roll" type="revolute">
    <origin rpy="0 0 0" xyz="0.0167 0.004 -0.02275"/>
    <parent link="r_hipjointupper"/>
    <child link="r_hipjointlower"/>
    <axis xyz="1.0 0.0 0.0"/>
    <limit effort="1.373" lower="-0.436332313" upper="0.3490658504" velocity="10.0"/>
  </joint>
  <joint name="r_hipjoint_pitch" type="revolute">
    <origin rpy="0 0 0" xyz="-0.01625 -0.0275 -0.0395"/>
    <parent link="r_hipjointlower"/>
    <child link="r_upperleg"/>
    <axis xyz="0.0 -1.0 0.0"/>
    <limit effort="1.373" lower="-1.745329252" upper="1.919862177" velocity="10.0"/>
  </joint>
  <joint name="r_knee_pitch" type="revolute">
    <origin rpy="0 0 0" xyz="0.0 0.0 -0.065"/>
    <parent link="r_upperleg"/>
    <child link="r_lowerleg"/>
    <axis xyz="-0.0 1.0 -0.0"/>
    <limit effort="1.373" lower="0.0" upper="2.792526803" velocity="10.0"/>
  </joint>
  <joint name="r_ankle_pitch" type="revolute">
    <origin rpy="0 0 0" xyz="-0.003363 -0.0005 -0.064913"/>
    <parent link="r_lowerleg"/>
    <child link="r_ankle"/>
    <axis xyz="0.0 1.0 -0.0"/>
    <limit effort="1.373" lower="-1.5707963267948966" upper="1.745329252" velocity="10.0"/>
  </joint>
  <joint name="r_ankle_roll" type="revolute">
    <origin rpy="0 0 0" xyz="0.01975 0.028 -0.0395"/>
    <parent link="r_ankle"/>
    <child link="r_foot"/>
    <axis xyz="1.0 0.0 0.0"/>
    <limit effort="1.373" lower="-0.3490658504" upper="0.5235987756" velocity="10.0"/>
  </joint>
</robot>

